    <visual>
      <geometry>
        <mesh filename="package://ur_e_description/meshes/ur30/visual/base.dae"/>
      </geometry>
      <origin xyz="0 0 0"/>
      <material name="LightGrey">
        <color rgba="0.7 0.7 0.7 1"/>
      </material>
    </visual>
    <collision>
      <geometry>
        <cylinder length="0.12739999999999999" radius="0.13"/>
      </geometry>
      <origin xyz="0 0 0.06369999999999999"/>
    </collision>
    <inertial>
      <mass value="4.0"/>
      <origin rpy="0 0 0" xyz="0.0 0.0 0.0"/>
      <inertia ixx="0.0061063308908" ixy="0.0" ixz="0.0" iyy="0.0061063308908" iyz="0.0" izz="0.01125"/>
    </inertial>
  </link>
  <joint name="shoulder_pan_joint" type="revolute">
    <parent link="base_link"/>
    <child link="shoulder_link"/>
    <origin rpy="0.0 0.0 0.0" xyz="0.0 0.0 0.2363"/>
    <axis xyz="0 0 1"/>
    <limit effort="330.0" lower="-6.283185307179586" upper="6.283185307179586" velocity="3.14"/>
    <dynamics damping="0.0" friction="0.0"/>
  </joint>
  <link name="shoulder_link">
    <visual>
      <geometry>
        <mesh filename="package://ur_e_description/meshes/ur30/visual/shoulder.dae"/>
      </geometry>
      <material name="LightGrey">
        <color rgba="0.7 0.7 0.7 1.0"/>
      </material>
¡¡¡¡</visual>
    <collision>
      <geometry>
        <cylinder length="0.225845" radius="0.1"/>
      </geometry>
      <origin xyz="0 0 -0.014532489999999995"/>
    </collision>
    <collision>
      <geometry>
        <cylinder length="0.35289991" radius="0.1"/>
      </geometry>
      <origin rpy="1.5707963267948966 0 0" xyz="0 0.176449955 0"/>
      
        /&gt;
      
    </collision>
    <inertial>
      <mass value="16.343"/>
      <origin rpy="0 0 0" xyz="0.0 0.0 0.0"/>
      <inertia ixx="0.06613328496334209" ixy="0.0" ixz="0.0" iyy="0.06613328496334209" iyz="0.0" izz="0.0459646875"/>
    </inertial>
  </link>
  <joint name="shoulder_lift_joint" type="revolute">
    <parent link="shoulder_link"/>
    <child link="upper_arm_link"/>
    <origin rpy="0.0 1.5707963267948966 0.0" xyz="0.0 0.2629 0.0"/>
    <axis xyz="0 1 0"/>
    <limit effort="330.0" lower="-6.283185307179586" upper="6.283185307179586" velocity="3.14"/>
    <dynamics damping="0.0" friction="0.0"/>
  </joint>
  <link name="upper_arm_link">
    <visual>
      <geometry>
        <mesh filename="package://ur_e_description/meshes/ur30/visual/upperarm.dae"/>
      </geometry>
      <material name="LightGrey">
        <color rgba="0.7 0.7 0.7 1.0"/>
      </material>
    </visual>
    <collision>
      <geometry>
        <cylinder length="0.26" radius="0.1"/>
      </geometry>
      <origin xyz="0 0 0.13"/>
    </collision>
    <!-- Todo -->
    <collision>
      <geometry>
        <cylinder length="0.637" radius="0.085"/>
      </geometry>
      <origin xyz="0 0 0.3185"/>
    </collision>
    <inertial>
      <mass value="28.542"/>
      <origin rpy="0 0 0" xyz="0.0 0.0 -0.3185"/>
      <inertia ixx="1.0052583518964984" ixy="0.0" ixz="0.0" iyy="1.0052583518964984" iyz="0.0" izz="0.080274375"/>
    </inertial>
  </link>
  <joint name="elbow_joint" type="revolute">
    <parent link="upper_arm_link"/>
    <child link="forearm_link"/>
    <origin rpy="0.0 0.0 0.0" xyz="0.0 -0.2197 0.637"/>
    <axis xyz="0 1 0"/>
    <limit effort="150.0" lower="-3.141592653589793" upper="3.141592653589793" velocity="3.14"/>
    <dynamics damping="0.0" friction="0.0"/>
  </joint>
  <link name="forearm_link">
    <visual>
      <geometry>
        <mesh filename="package://ur_e_description/meshes/ur30/visual/forearm.dae"/>
      </geometry>
      <material name="LightGrey">
        <color rgba="0.7 0.7 0.7 1.0"/>
      </material>
    </visual>
    <collision>
      <geometry>
        <cylinder length="0.37671287" radius="0.085"/>
      </geometry>
      <origin rpy="1.5707963267948966 0 0" xyz="0 0.10985000499999999 0"/>
    </collision>
    <collision>
      <geometry>
        <cylinder length="0.15" radius="0.085"/>
      </geometry>
      <origin rpy="0 0 0" xyz="0 0 0.075"/>
    </collision>
    <collision>
      <geometry>
        <cylinder length="0.1" radius="0.075"/>
      </geometry>
      <origin rpy="0 0 0" xyz="0 0 0.2"/>
    </collision>
    <collision>
      <geometry>
        <cylinder length="0.5037" radius="0.06"/>
      </geometry>
      <origin rpy="0 0 0" xyz="0 0 0.25185"/>
    </collision>
    <inertial>
      <mass value="7.156"/>
      <origin rpy="0 0 0" xyz="0.0 0.0 -0.25185"/>
      <inertia ixx="0.16136099092557782" ixy="0.0" ixz="0.0" iyy="0.16136099092557782" iyz="0.0" izz="0.02012625"/>
    </inertial>
  </link>
  <joint name="wrist_1_joint" type="revolute">
    <parent link="forearm_link"/>
    <child link="wrist_1_link"/>
    <origin rpy="0.0 1.5707963267948966 0.0" xyz="0.0 0.0 0.5037"/>
    <axis xyz="0 1 0"/>
    <limit effort="54.0" lower="-6.283185307179586" upper="6.283185307179586" velocity="6.28"/>
    <dynamics damping="0.0" friction="0.0"/>
  </joint>
  <link name="wrist_1_link">
    <visual>
      <geometry>
        <mesh filename="package://ur_e_description/meshes/ur30/visual/wrist1.dae"/>
      </geometry>
      <material name="LightGrey">
        <color rgba="0.7 0.7 0.7 1.0"/>
      </material>
    </visual>
    <collision>
      <geometry>
        <cylinder length="0.26236601" radius="0.06"/>
      </geometry>
      <origin rpy="1.5707963267948966 0 0" xyz="0 0.0789 0"/>
    </collision>
    <inertial>
      <mass value="3.054"/>
      <origin rpy="0 0 0" xyz="0.0 0.1578 0.0"/>
      <inertia ixx="0.007959484316204999" ixy="0.0" ixz="0.0" iyy="0.007959484316204999" iyz="0.0" izz="0.008589374999999998"/>
    </inertial>
  </link>
  <joint name="wrist_2_joint" type="revolute">
    <parent link="wrist_1_link"/>
    <child link="wrist_2_link"/>
    <origin rpy="0.0 0.0 0.0" xyz="0.0 0.1578 0.0"/>
    <axis xyz="0 0 1"/>
    <limit effort="54.0" lower="-6.283185307179586" upper="6.283185307179586" velocity="6.28"/>
    <dynamics damping="0.0" friction="0.0"/>
  </joint>
  <link name="wrist_2_link">
    <visual>
      <geometry>
        <mesh filename="package://ur_e_description/meshes/ur30/visual/wrist2.dae"/>
      </geometry>
      <material name="LightGrey">
        <color rgba="0.7 0.7 0.7 1.0"/>
      </material>
    </visual>
    <collision>
      <geometry>
        <cylinder length="0.1543" radius="0.06"/>
      </geometry>
      <origin rpy="0 0 0" xyz="0 0 0.07965"/>
    </collision>
    <inertial>
      <mass value="3.126"/>
      <origin rpy="0 0 0" xyz="0.0 0.0 0.1593"/>
      <inertia ixx="0.008147134241144998" ixy="0.0" ixz="0.0" iyy="0.008147134241144998" iyz="0.0" izz="0.008791875"/>
    </inertial>
  </link>
  <joint name="wrist_3_joint" type="revolute">
    <parent link="wrist_2_link"/>
    <child link="wrist_3_link"/>
    <origin rpy="0.0 0.0 0.0" xyz="0.0 0.0 0.1593"/>
    <axis xyz="0 1 0"/>
    <limit effort="54.0" lower="-6.283185307179586" upper="6.283185307179586" velocity="6.28"/>
    <dynamics damping="0.0" friction="0.0"/>
  </joint>
  <link name="wrist_3_link">
    <visual>
      <geometry>
        <mesh filename="package://ur_e_description/meshes/ur30/visual/wrist3.dae"/>
      </geometry>
      <material name="LightGrey">
        <color rgba="0.7 0.7 0.7 1.0"/>
      </material>
    </visual>
    <collision>
      <geometry>
        <cylinder length="0.20799186" radius="0.06"/>
      </geometry>
      <origin rpy="1.5707963267948966  0 0" xyz="0 0.05030406999999999 0"/>
    </collision>
    <inertial>
      <mass value="0.926"/>
      <origin rpy="1.5707963267948966 0 0" xyz="0.0 0.1293 0.0"/>
      <inertia ixx="0.0006617039019850002" ixy="0.0" ixz="0.0" iyy="0.0006617039019850002" iyz="0.0" izz="0.000937575"/>
    </inertial>
  </link>
  <joint name="ee_fixed_joint" type="fixed">
    <parent link="wrist_3_link"/>
    <child link="ee_link"/>
    <origin rpy="0.0 0.0 1.5707963267948966" xyz="0.0 0.1543 0.0"/>
  </joint>
  <link name="ee_link">
    <collision>
      <geometry>
        <box size="0.01 0.01 0.01"/>
      </geometry>
      <origin rpy="0 0 0" xyz="-0.01 0 0"/>
    </collision>
  </link>
  <transmission name="shoulder_pan_trans">
    <type>transmission_interface/SimpleTransmission</type>
    <joint name="shoulder_pan_joint">
      <hardwareInterface>hardware_interface/PositionJointInterface</hardwareInterface>
    </joint>
    <actuator name="shoulder_pan_motor">
      <mechanicalReduction>1</mechanicalReduction>
    </actuator>
  </transmission>
  <transmission name="shoulder_lift_trans">
    <type>transmission_interface/SimpleTransmission</type>
    <joint name="shoulder_lift_joint">
      <hardwareInterface>hardware_interface/PositionJointInterface</hardwareInterface>
    </joint>
    <actuator name="shoulder_lift_motor">
      <mechanicalReduction>1</mechanicalReduction>
    </actuator>
  </transmission>
  <transmission name="elbow_trans">
    <type>transmission_interface/SimpleTransmission</type>
    <joint name="elbow_joint">
      <hardwareInterface>hardware_interface/PositionJointInterface</hardwareInterface>
    </joint>
    <actuator name="elbow_motor">
      <mechanicalReduction>1</mechanicalReduction>
    </actuator>
  </transmission>
  <transmission name="wrist_1_trans">
    <type>transmission_interface/SimpleTransmission</type>
    <joint name="wrist_1_joint">
      <hardwareInterface>hardware_interface/PositionJointInterface</hardwareInterface>
    </joint>
    <actuator name="wrist_1_motor">
      <mechanicalReduction>1</mechanicalReduction>
    </actuator>
  </transmission>
  <transmission name="wrist_2_trans">
    <type>transmission_interface/SimpleTransmission</type>
    <joint name="wrist_2_joint">
      <hardwareInterface>hardware_interface/PositionJointInterface</hardwareInterface>
    </joint>
    <actuator name="wrist_2_motor">
      <mechanicalReduction>1</mechanicalReduction>
    </actuator>
  </transmission>
  <transmission name="wrist_3_trans">
    <type>transmission_interface/SimpleTransmission</type>
    <joint name="wrist_3_joint">
      <hardwareInterface>hardware_interface/PositionJointInterface</hardwareInterface>
    </joint>
    <actuator name="wrist_3_motor">
      <mechanicalReduction>1</mechanicalReduction>
    </actuator>
  </transmission>
  <gazebo reference="shoulder_link">
    <selfCollide>true</selfCollide>
  </gazebo>
  <gazebo reference="upper_arm_link">
    <selfCollide>true</selfCollide>
  </gazebo>
  <gazebo reference="forearm_link">
    <selfCollide>true</selfCollide>
  </gazebo>
  <gazebo reference="wrist_1_link">
    <selfCollide>true</selfCollide>
  </gazebo>
  <gazebo reference="wrist_3_link">
    <selfCollide>true</selfCollide>
  </gazebo>
  <gazebo reference="wrist_2_link">
    <selfCollide>true</selfCollide>
  </gazebo>
  <gazebo reference="ee_link">
    <selfCollide>true</selfCollide>
  </gazebo>
  <!-- ROS base_link to UR 'Base' Coordinates transform -->
  <link name="base"/>
  <joint name="base_link-base_fixed_joint" type="fixed">
    <!-- NOTE: this rotation is only needed as long as base_link itself is
                 not corrected wrt the real robot (ie: rotated over 180
                 degrees)
      -->
    <origin rpy="0 0 -3.141592653589793" xyz="0 0 0"/>
    <parent link="base_link"/>
    <child link="base"/>
  </joint>
  <!-- Frame coincident with all-zeros TCP on UR controller -->
  <link name="tool0"/>
  <joint name="wrist_3_link-tool0_fixed_joint" type="fixed">
    <origin rpy="-1.5707963267948966 0 0" xyz="0 0.1543 0"/>
    <parent link="wrist_3_link"/>
    <child link="tool0"/>
  </joint>
  <sr_ignore_collisions link1="base_link" link2="shoulder_link"/>
  <sr_ignore_collisions link1="base_link" link2="upper_arm_link"/>
  <sr_ignore_collisions link1="shoulder_link" link2="upper_arm_link"/>
  <sr_ignore_collisions link1="upper_arm_link" link2="forearm_link"/>
  <sr_ignore_collisions link1="forearm_link" link2="wrist_1_link"/>
  <sr_ignore_collisions link1="forearm_link" link2="wrist_2_link"/>
  <sr_ignore_collisions link1="wrist_1_link" link2="wrist_2_link"/>
  <sr_ignore_collisions link1="wrist_1_link" link2="wrist_3_link"/>
  <sr_ignore_collisions link1="wrist_2_link" link2="wrist_3_link"/>
  <sr_ignore_collisions link1="wrist_3_link" link2="ee_link"/>
  <link name="world"/>
  <joint name="world_joint" type="fixed">
    <parent link="world"/>
    <child link="base_link"/>
    <origin rpy="0.0 0.0 0.0" xyz="0.0 0.0 0.0"/>
  </joint>
</robot>