<mujoco model="ur30">
  <option iterations="50" timestep="0.001" solver="PGS" gravity="0 0 -9.81" />

  <compiler angle="radian" meshdir="meshes" eulerseq="zyx" autolimits="true" />

  <default>
    <joint limited="true" damping="0.01" armature="0.01" frictionloss="0.01" />
    <geom condim="4" contype="1" conaffinity="15" friction="0.9 0.2 0.2" solref="0.001 2" />
    <motor ctrllimited="true" />
    <equality solref="0.001 2" />
    <default class="visualgeom">
      <geom material="visualgeom" condim="1" contype="0" conaffinity="0" />
    </default>
  </default>

  <worldbody>
    <light directional="true" diffuse="0.4 0.4 0.4" specular="0.1 0.1 0.1" pos="0 0 5.0" dir="0 0 -1" castshadow="false" />
    <light directional="true" diffuse="0.6 0.6 0.6" specular="0.2 0.2 0.2" pos="0 0 4" dir="0 0 -1" />
    <geom name="ground" type="plane" pos="0 0 0" size="100 100 0.001" quat="1 0 0 0" material="matplane" condim="3" conaffinity="15" />
    <camera name="fixed" pos="0 -3.0 0.4363" xyaxes="1 0 0 0 0 1" />
    <camera name="track" mode="trackcom" pos="0 -3.0 0.4363" xyaxes="1 0 0 0 0 1" />
    
    <body name="root" pos="0 0 -0.06369999999999999" quat="1 0 0 0">
      <freejoint name="root" />
      <site name="imu" size="0.01" pos="0 0 0" />
      <geom size="0.13 0.0637" pos="0 0 0.0637" type="cylinder" rgba="0.7 0.7 0.7 1" contype="1" conaffinity="0" density="0" group="1" class="visualgeom" />
      <geom type="cylinder" rgba="0.7 0.7 0.7 1" pos="0 0 0.0637" />
      
      <body name="shoulder_link" pos="0 0 0.2363">
        <inertial pos="0 0 0" mass="16.343" diaginertia="0.0661333 0.0661333 0.0459647" />
        <geom size="0.1 0.112922" pos="0 0 -0.0145325" type="cylinder" rgba="0.7 0.7 0.7 1" contype="1" conaffinity="0" density="0" group="1" class="visualgeom" />
        <geom type="cylinder" rgba="0.7 0.7 0.7 1" pos="0 0 -0.0145325" />
        <geom size="0.1 0.17645" pos="0 0.17645 0" quat="0.707107 0.707107 0 0" type="cylinder" rgba="0.7 0.7 0.7 1" contype="1" conaffinity="0" density="0" group="1" class="visualgeom" />
        <geom type="cylinder" rgba="0.7 0.7 0.7 1" pos="0 0.17645 0" quat="0.707107 0.707107 0 0" />
       
        <body name="upper_arm_link" pos="0 0.2629 0" quat="0.707107 0 0.707107 0">
          <inertial pos="0 0 -0.3185" mass="28.542" diaginertia="1.00526 1.00526 0.0802744" />
          <joint name="shoulder_lift_joint" pos="0 0 0" axis="0 1 0" range="-6.28319 6.28319" actuatorfrcrange="-330 330" />
          <geom size="0.1 0.13" pos="0 0 0.13" type="cylinder" rgba="0.7 0.7 0.7 1" contype="1" conaffinity="0" density="0" group="1" class="visualgeom" />
          <geom type="cylinder" rgba="0.7 0.7 0.7 1" pos="0 0 0.13" />
          <geom size="0.085 0.3185" pos="0 0 0.3185" type="cylinder" rgba="0.7 0.7 0.7 1" contype="1" conaffinity="0" density="0" group="1" class="visualgeom" />
          <geom type="cylinder" rgba="0.7 0.7 0.7 1" pos="0 0 0.3185" />
         
          <body name="forearm_link" pos="0 -0.2197 0.637">
            <inertial pos="0 0 -0.25185" mass="7.156" diaginertia="0.161361 0.161361 0.0201262" />
            <joint name="elbow_joint" pos="0 0 0" axis="0 1 0" range="-3.14159 3.14159" actuatorfrcrange="-150 150" />
            <geom size="0.085 0.188356" pos="0 0.10985 0" quat="0.707107 0.707107 0 0" type="cylinder" rgba="0.7 0.7 0.7 1" contype="1" conaffinity="0" density="0" group="1" class="visualgeom" />
            <geom type="cylinder" rgba="0.7 0.7 0.7 1" pos="0 0.10985 0" quat="0.707107 0.707107 0 0" />
            <geom size="0.085 0.075" pos="0 0 0.075" type="cylinder" rgba="0.7 0.7 0.7 1" contype="1" conaffinity="0" density="0" group="1" class="visualgeom" />
            <geom type="cylinder" rgba="0.7 0.7 0.7 1" pos="0 0 0.075" />
            <geom size="0.075 0.05" pos="0 0 0.2" type="cylinder" rgba="0.7 0.7 0.7 1" contype="1" conaffinity="0" density="0" group="1" class="visualgeom" />
            <geom type="cylinder" rgba="0.7 0.7 0.7 1" pos="0 0 0.2" />
            <geom size="0.06 0.25185" pos="0 0 0.25185" type="cylinder" rgba="0.7 0.7 0.7 1" contype="1" conaffinity="0" density="0" group="1" class="visualgeom" />
            <geom type="cylinder" rgba="0.7 0.7 0.7 1" pos="0 0 0.25185" />
            
            <body name="wrist_1_link" pos="0 0 0.5037" quat="0.707107 0 0.707107 0">
              <inertial pos="0 0.1578 0" quat="0.5 0.5 -0.5 0.5" mass="3.054" diaginertia="0.00858937 0.00795948 0.00795948" />
              <joint name="wrist_1_joint" pos="0 0 0" axis="0 1 0" range="-6.28319 6.28319" actuatorfrcrange="-54 54" />
              <geom size="0.06 0.131183" pos="0 0.0789 0" quat="0.707107 0.707107 0 0" type="cylinder" rgba="0.7 0.7 0.7 1" contype="1" conaffinity="0" density="0" group="1" class="visualgeom" />
              <geom type="cylinder" rgba="0.7 0.7 0.7 1" pos="0 0.0789 0" quat="0.707107 0.707107 0 0" />
             
              <body name="wrist_2_link" pos="0 0.1578 0">
                <inertial pos="0 0 0.1593" quat="0.5 0.5 -0.5 0.5" mass="3.126" diaginertia="0.00879187 0.00814713 0.00814713" />
                <joint name="wrist_2_joint" pos="0 0 0" axis="0 0 1" range="-6.28319 6.28319" actuatorfrcrange="-54 54" />
                <geom size="0.06 0.07715" pos="0 0 0.07965" type="cylinder" rgba="0.7 0.7 0.7 1" contype="1" conaffinity="0" density="0" group="1" class="visualgeom" />
                <geom type="cylinder" rgba="0.7 0.7 0.7 1" pos="0 0 0.07965" />
               
                <body name="wrist_3_link" pos="0 0 0.1593">
                  <inertial pos="0 0.129316 0" quat="0.5 0.5 -0.5 0.5" mass="0.927" diaginertia="0.000937816 0.000661945 0.000661721" />
                  <joint name="wrist_3_joint" pos="0 0 0" axis="0 1 0" range="-6.28319 6.28319" actuatorfrcrange="-54 54" />
                  <geom size="0.06 0.103996" pos="0 0.0503041 0" quat="0.707107 0.707107 0 0" type="cylinder" rgba="0.7 0.7 0.7 1" contype="1" conaffinity="0" density="0" group="1" class="visualgeom" />
                  <geom type="cylinder" rgba="0.7 0.7 0.7 1" pos="0 0.0503041 0" quat="0.707107 0.707107 0 0" />
                  <geom size="0.005 0.005 0.005" pos="0 0.1443 0" quat="0.707107 0 0 0.707107" type="box" contype="1" conaffinity="0" density="0" group="1" class="visualgeom" />
                  <geom type="box" rgba="" size="0.005 0.005 0.005" pos="0 0.1443 0" quat="0.707107 0 0 0.707107" />
                </body>
              </body>
            </body>
          </body>
        </body>
      </body>
    </body>
  </worldbody>

  <asset>
    <texture name="texplane" type="2d" builtin="checker" rgb1=".0 .0 .0" rgb2=".8 .8 .8" width="100" height="100" />
    <material name="matplane" reflectance="0." texture="texplane" texrepeat="1 1" texuniform="true" />
    <material name="visualgeom" rgba="0.5 0.9 0.2 1" />
  </asset>

  <actuator>
    <motor name="shoulder_pan_joint" joint="shoulder_pan_joint" ctrllimited="true" ctrlrange="-330 330" gear="1" />
    <motor name="shoulder_lift_joint" joint="shoulder_lift_joint" ctrllimited="true" ctrlrange="-330 330" gear="1" />
    <motor name="elbow_joint" joint="elbow_joint" ctrllimited="true" ctrlrange="-150 150" gear="1" />
    <motor name="wrist_1_joint" joint="wrist_1_joint" ctrllimited="true" ctrlrange="-54 54" gear="1" />
    <motor name="wrist_2_joint" joint="wrist_2_joint" ctrllimited="true" ctrlrange="-54 54" gear="1" />
    <motor name="wrist_3_joint" joint="wrist_3_joint" ctrllimited="true" ctrlrange="-54 54" gear="1" />
  </actuator>

  <sensor>
    <actuatorpos name="shoulder_pan_joint_p" actuator="shoulder_pan_joint" />
    <actuatorvel name="shoulder_pan_joint_v" actuator="shoulder_pan_joint" />
    <actuatorfrc name="shoulder_pan_joint_f" actuator="shoulder_pan_joint" noise="0.001" />
    <actuatorpos name="shoulder_lift_joint_p" actuator="shoulder_lift_joint" />
    <actuatorvel name="shoulder_lift_joint_v" actuator="shoulder_lift_joint" />
    <actuatorfrc name="shoulder_lift_joint_f" actuator="shoulder_lift_joint" noise="0.001" />
    <actuatorpos name="elbow_joint_p" actuator="elbow_joint" />
    <actuatorvel name="elbow_joint_v" actuator="elbow_joint" />
    <actuatorfrc name="elbow_joint_f" actuator="elbow_joint" noise="0.001" />
    <actuatorpos name="wrist_1_joint_p" actuator="wrist_1_joint" />
    <actuatorvel name="wrist_1_joint_v" actuator="wrist_1_joint" />
    <actuatorfrc name="wrist_1_joint_f" actuator="wrist_1_joint" noise="0.001" />
    <actuatorpos name="wrist_2_joint_p" actuator="wrist_2_joint" />
    <actuatorvel name="wrist_2_joint_v" actuator="wrist_2_joint" />
    <actuatorfrc name="wrist_2_joint_f" actuator="wrist_2_joint" noise="0.001" />
    <actuatorpos name="wrist_3_joint_p" actuator="wrist_3_joint" />
    <actuatorvel name="wrist_3_joint_v" actuator="wrist_3_joint" />
    <actuatorfrc name="wrist_3_joint_f" actuator="wrist_3_joint" noise="0.001" />
    <framequat name="orientation" objtype="site" noise="0.001" objname="imu" />
    <gyro name="angular-velocity" site="imu" noise="0.005" cutoff="34.9" />
  </sensor>
</mujoco>